Workbook

Sheet Devis
A1: SA LA GARONNE — Devis refonte outil métier (brouillon)
A2: PMC Marketing — septembre 2026 — montants HT
A4: TJM (€ HT / jour) | B4: 600 | C4: ← à ajuster : toutes les lignes se recalculent
A5: Remise engagement global | B5: 0 | C5: appliquée si le client commande tous les lots de base ensemble
A6: Bleu = à modifier · noir = calculé · Option = ligne facultative, exclue du total de base
A8: Lot | B8: Ligne | C8: Description | D8: Jours | E8: Montant HT | F8: Type
A9: Lot 0 | B9: Lancement
A10: Lot 0 | B10: Récupération des sources WinDev et export complet de la base HFSQL | C10: Exercice de la clause de cession, extraction ODBC, sauvegarde hors serveur, lecture de l'analyse (modèle de données). | D10: 1 | E10: =D10*$B$4 -> 600 | F10: Base
A11: Lot 0 | B11: Entretiens bureau d'études et chef de chantier | C11: Deux entretiens ciblés ; confirmation du périmètre et des documents à reproduire. | D11: 1 | E11: =D11*$B$4 -> 600 | F11: Base
A12: Lot 0 | B12: Modèle de données, rôles et droits | C12: Schéma cible, rôles nommés, matrice de droits par module et champs sensibles, registre RGPD. | D12: 2 | E12: =D12*$B$4 -> 1200 | F12: Base
A13: Lot 0 | B13: Design system et maquettes du lot 1 | C13: Identité de l'application selon la charte, composants de base, maquettes des écrans clés QSE. | D13: 2 | E13: =D13*$B$4 -> 1200 | F13: Base
A14: Lot 0 | B14: Mise en place des environnements | C14: Vercel (région EU), PostgreSQL managé, stockage objet S3, envoi d'emails, dépôt de code au nom du client, CI. | D14: 1 | E14: =D14*$B$4 -> 600 | F14: Base
B15: Sous-total Lot 0 (base) | D15: =SUMIF(F10:F14,"Base",D10:D14) -> 7 | E15: =SUMIF(F10:F14,"Base",E10:E14) -> 4200 | F15: =SUMIF(F10:F14,"Option",E10:E14) -> 0
A17: Lot 1 | B17: Socle et conformité (QSE)
A18: Lot 1 | B18: Authentification, rôles, droits, journal d'accès | C18: Comptes nominatifs, rôles, masquage des champs sensibles, périmètre « mes données », traçabilité. | D18: 3 | E18: =D18*$B$4 -> 1800 | F18: Base
A19: Lot 1 | B19: Composants partagés | C19: Liste filtrable/triable/exportable, fiche par rôle, référentiel générique, GED à dates de validité avec droits par dossier. | D19: 4 | E19: =D19*$B$4 -> 2400 | F19: Base
A20: Lot 1 | B20: Répertoire des organisations et référentiels | C20: Table unifiée typée (clients, MOE, sous-traitants, organismes, fournisseurs) ; référentiels paramétrables. | D20: 2 | E20: =D20*$B$4 -> 1200 | F20: Base
A21: Lot 1 | B21: Salariés : fiche, listes, arrêts de travail, dossier amiante | C21: Fiche réduite par rôle, intérimaires et stagiaires, arrêts avec déclaration, dossier amiante à conservation longue. | D21: 3 | E21: =D21*$B$4 -> 1800 | F21: Base
A22: Lot 1 | B22: Registre des habilitations | C22: Permis, formations, autorisations, examens médicaux avec justificatifs PDF, statuts, distinction expiré / plus requis, vue consolidée. | D22: 3 | E22: =D22*$B$4 -> 1800 | F22: Base
A23: Lot 1 | B23: Parc matériel : inventaire, classification, fiche, documents | C23: Reprise de la classification, fiche identité/achat, photos, documents à validité (CT, VGP, assurance, homologation). | D23: 3 | E23: =D23*$B$4 -> 1800 | F23: Base
A24: Lot 1 | B24: Plans d'entretien et échéances | C24: Seuils à trois niveaux par km / heures / durée, fournitures, vidanges, statut par équipement. | D24: 3 | E24: =D24*$B$4 -> 1800 | F24: Base
A25: Lot 1 | B25: Interventions, tâches terrain, rapports d'utilisation, disques | C25: Journal atelier, signalements panne/casse avec suivi, points de contrôle, compteurs et carburant, disques tachygraphe. | D25: 3 | E25: =D25*$B$4 -> 1800 | F25: Base
A26: Lot 1 | B26: Éditions réglementaires TICPE et Défense | C26: Exports conformes aux documents actuels. | D26: 1.5 | E26: =D26*$B$4 -> 900 | F26: Base
A27: Lot 1 | B27: Moteur d'alertes, tableau de bord, emails | C27: Échéances centralisées (habilitations, médical, documents, entretiens), tableau de bord par rôle, récapitulatif hebdomadaire. | D27: 3 | E27: =D27*$B$4 -> 1800 | F27: Base
A28: Lot 1 | B28: Reprise des données salariés et matériel | C28: Nettoyage (doublons, valeurs de test), migration des habilitations avec justificatifs, du parc et des plans d'entretien. | D28: 2.5 | E28: =D28*$B$4 -> 1500 | F28: Base
A29: Lot 1 | B29: Recette, formation QSE, mise en production | C29: Recette avec l'utilisatrice, corrections, formation, bascule. | D29: 1.5 | E29: =D29*$B$4 -> 900 | F29: Base
B30: Sous-total Lot 1 (base) | D30: =SUMIF(F18:F29,"Base",D18:D29) -> 32.5 | E30: =SUMIF(F18:F29,"Base",E18:E29) -> 19500 | F30: =SUMIF(F18:F29,"Option",E18:E29) -> 0
A32: Lot 2 | B32: Commercial (bureau d'études)
A33: Lot 2 | B33: Affaires : liste et fiche | C33: Général, groupement, correspondance, notes, GED, BPU en pièce jointe, verrouillage après remise, statuts. | D33: 4 | E33: =D33*$B$4 -> 2400 | F33: Base
A34: Lot 2 | B34: Marchés et chantiers | C34: Accords-cadres, chantiers rattachés, classification SS3/SS4, données PPSPS, numérotation automatique. | D34: 2.5 | E34: =D34*$B$4 -> 1500 | F34: Base
A35: Lot 2 | B35: Certificats de capacité | C35: Croisement identités FNTP / réseaux / zones, rattachement aux chantiers, édition PDF. | D35: 2 | E35: =D35*$B$4 -> 1200 | F35: Base
A36: Lot 2 | B36: Éditions PDF et alertes commerciales | C36: Fiche affaire imprimable, alertes sur dates de remise et échéances de marchés. | D36: 1.5 | E36: =D36*$B$4 -> 900 | F36: Base
A37: Lot 2 | B37: Reprise des données commerciales | C37: Affaires, marchés, chantiers, répertoires. | D37: 1 | E37: =D37*$B$4 -> 600 | F37: Base
A38: Lot 2 | B38: Recette, formation bureau d'études, arrêt de l'ancien outil | C38: Recette, formation, période de recouvrement, extinction. | D38: 1 | E38: =D38*$B$4 -> 600 | F38: Base
B39: Sous-total Lot 2 (base) | D39: =SUMIF(F33:F38,"Base",D33:D38) -> 12 | E39: =SUMIF(F33:F38,"Base",E33:E38) -> 7200 | F39: =SUMIF(F33:F38,"Option",E33:E38) -> 0
A41: Lot 3 | B41: Terrain (chefs de chantier)
A42: Lot 3 | B42: Application mobile PWA | C42: Vue chef de chantier : mes chantiers, documents, photos, installation sur tablette. | D42: 4 | E42: =D42*$B$4 -> 2400 | F42: Base
A43: Lot 3 | B43: Signalements, checklists, rapports depuis le terrain | C43: Panne/casse, points de contrôle avant utilisation, compteurs et carburant, photos horodatées. | D43: 2 | E43: =D43*$B$4 -> 1200 | F43: Base
A44: Lot 3 | B44: Formation et accompagnement terrain | C44: Formation des chefs de chantier, ajustements sur retours. | D44: 1 | E44: =D44*$B$4 -> 600 | F44: Base
A45: Lot 3 | B45: Mode hors-ligne et synchronisation | C45: Base locale, file d'attente, gestion des conflits. Retenu si la couverture réseau des chantiers l'exige. | D45: 6 | E45: =D45*$B$4 -> 3600 | F45: Option
...

Sheet Récurrent
A1: Exploitation et maintenance — mensuel HT
A2: Engagement 12 mois à compter de la mise en production du lot 1. Évolutions hors forfait facturées au TJM.
A4: Poste | B4: Contenu | C4: € HT / mois
A5: Hébergement et sauvegardes | B5: Vercel Pro (EU), PostgreSQL managé, stockage documents, emails transactionnels, nom de domaine ; sauvegardes quotidiennes, test de restauration trimestriel, supervision. Coûts d'infrastructure inclus jusqu'à 100 Go de documents. | C5: 150
A6: Maintenance corrective et support | B6: Correction des anomalies sous 48 h ouvrées, support par email aux utilisateurs clés, mises à jour de sécurité, petites évolutions dans la limite d'une demi-journée par mois. | C6: 350
A7: Total mensuel | C7: =SUM(C5:C6) -> 500
A8: Total annuel | C8: =C7*12 -> 6000
A10: Hypothèse : coûts d'infrastructure estimés à 60–90 €/mois au démarrage (Vercel Pro 20 €, base managée 25 €, stockage et emails 15–40 €). Le poste hébergement couvre ces coûts et la supervision.

Sheet Échéancier
A1: Conditions de règlement proposées
A3: Étape | B3: Déclencheur | C3: Part | D3: Montant HT
A4: Acompte à la commande | B4: Signature du devis | C4: 0.3 | D4: =C4*Devis!$E$59 -> 12870
A5: Livraison lot 1 | B5: Recette QSE validée, mise en production | C5: 0.3 | D5: =C5*Devis!$E$59 -> 12870
A6: Livraison lot 2 | B6: Recette bureau d'études validée | C6: 0.15 | D6: =C6*Devis!$E$59 -> 6435
A7: Livraison lot 3 | B7: Recette terrain validée | C7: 0.1 | D7: =C7*Devis!$E$59 -> 4290
A8: Livraison lot 4 | B8: Recette validée | C8: 0.15 | D8: =C8*Devis!$E$59 -> 6435
A9: Total | C9: =SUM(C4:C8) -> 1 | D9: =SUM(D4:D8) -> 42900
A11: Calculé sur le total base après remise (feuille Devis). Les options sont facturées à la livraison du lot concerné.
